{
  "id": "LoMUUgL_160",
  "conversations": [
    {
      "from": "human",
      "value": "still error : PS C:\\Users\\Dan.QTIS\\Desktop\\Dan\\All Projects Full\\Ai App> c:; cd 'c:\\Users\\Dan.QTIS\\Desktop\\Dan\\All Projects Full\\Ai App'; & 'C:\\Program Files\\Python311\\python.exe' 'c:\\Users\\Dan.QTIS\\.vscode\\extensions\\ms-python.python-2023.4.0\\pythonFiles\\lib\\python\\debugpy\\adapter/../..\\debugpy\\launcher' '50397' '--' 'c:\\Users\\Dan.QTIS\\Desktop\\Dan\\All Projects Full\\Ai App\\main.py' \nTraceback (most recent call last):\n File \"C:\\Program Files\\Python311\\Lib\\runpy.py\", line 198, in \\_run\\_module\\_as\\_main\n return \\_run\\_code(code, main\\_globals, None,\n ^^^^^^^^^^^^^^^^^^^^^^^^^^^^^^^^^^^\n File \"C:\\Program Files\\Python311\\Lib\\runpy.py\", line 88, in \\_run\\_code\n exec(code, run\\_globals)\n File \"c:\\Users\\Dan.QTIS\\.vscode\\extensions\\ms-python.python-2023.4.0\\pythonFiles\\lib\\python\\debugpy\\adapter/../..\\debugpy\\launcher/../..\\debugpy\\\\_\\_main\\_\\_.py\", line 39, in \n cli.main()\n File \"c:\\Users\\Dan.QTIS\\.vscode\\extensions\\ms-python.python-2023.4.0\\pythonFiles\\lib\\python\\debugpy\\adapter/../..\\debugpy\\launcher/../..\\debugpy/..\\debugpy\\server\\cli.py\", line 430, in main\n run()\n File \"c:\\Users\\Dan.QTIS\\.vscode\\extensions\\ms-python.python-2023.4.0\\pythonFiles\\lib\\python\\debugpy\\adapter/../..\\debugpy\\launcher/../..\\debugpy/..\\debugpy\\server\\cli.py\", line 284, in run\\_file\n runpy.run\\_path(target, run\\_name=\"\\_\\_main\\_\\_\")\n File \"c:\\Users\\Dan.QTIS\\.vscode\\extensions\\ms-python.python-2023.4.0\\pythonFiles\\lib\\python\\debugpy\\\\_vendored\\pydevd\\\\_pydevd\\_bundle\\pydevd\\_runpy.py\", line 320, in run\\_path\n code, fname = \\_get\\_code\\_from\\_file(run\\_name, path\\_name)\n ^^^^^^^^^^^^^^^^^^^^^^^^^^^^^^^^^^^^^^^^\n File \"c:\\Users\\Dan.QTIS\\.vscode\\extensions\\ms-python.python-2023.4.0\\pythonFiles\\lib\\python\\debugpy\\\\_vendored\\pydevd\\\\_pydevd\\_bundle\\pydevd\\_runpy.py\", line 294, in \\_get\\_code\\_from\\_file\n code = compile(f.read(), fname, 'exec')\n ^^^^^^^^^^^^^^^^^^^^^^^^^^^^^^^^\n File \"c:\\Users\\Dan.QTIS\\Desktop\\Dan\\All Projects Full\\Ai App\\main.py\", line 108\n def speak\\_button\\_clicked():\nIndentationError: expected an indented block after 'except' statement on line 105\nPS C:\\Users\\Dan.QTIS\\Desktop\\Dan\\All Projects Full\\Ai App> c:; cd 'c:\\Users\\Dan.QTIS\\Desktop\\Dan\\All Projects Full\\Ai App'; & 'C:\\Program Files\\Python311\\python.exe' 'c:\\Users\\Dan.QTIS\\.vscode\\extensions\\ms-python.python-2023.4.0\\pythonFiles\\lib\\python\\debugpy\\adapter/../..\\debugpy\\launcher' '50409' '--' 'c:\\Users\\Dan.QTIS\\Desktop\\Dan\\All Projects Full\\Ai App\\main.py' \nTraceback (most recent call last):\n File \"C:\\Program Files\\Python311\\Lib\\runpy.py\", line 198, in \\_run\\_module\\_as\\_main\n return \\_run\\_code(code, main\\_globals, None,\n ^^^^^^^^^^^^^^^^^^^^^^^^^^^^^^^^^^^\n File \"C:\\Program Files\\Python311\\Lib\\runpy.py\", line 88, in \\_run\\_code\n exec(code, run\\_globals)\n File \"c:\\Users\\Dan.QTIS\\.vscode\\extensions\\ms-python.python-2023.4.0\\pythonFiles\\lib\\python\\debugpy\\adapter/../..\\debugpy\\launcher/../..\\debugpy\\\\_\\_main\\_\\_.py\", line 39, in \n cli.main()\n File \"c:\\Users\\Dan.QTIS\\.vscode\\extensions\\ms-python.python-2023.4.0\\pythonFiles\\lib\\python\\debugpy\\adapter/../..\\debugpy\\launcher/../..\\debugpy/..\\debugpy\\server\\cli.py\", line 430, in main\n run()\n File \"c:\\Users\\Dan.QTIS\\.vscode\\extensions\\ms-python.python-2023.4.0\\pythonFiles\\lib\\python\\debugpy\\adapter/../..\\debugpy\\launcher/../..\\debugpy/..\\debugpy\\server\\cli.py\", line 284, in run\\_file\n runpy.run\\_path(target, run\\_name=\"\\_\\_main\\_\\_\")\n File \"c:\\Users\\Dan.QTIS\\.vscode\\extensions\\ms-python.python-2023.4.0\\pythonFiles\\lib\\python\\debugpy\\\\_vendored\\pydevd\\\\_pydevd\\_bundle\\pydevd\\_runpy.py\", line 320, in run\\_path\n code, fname = \\_get\\_code\\_from\\_file(run\\_name, path\\_name)\n ^^^^^^^^^^^^^^^^^^^^^^^^^^^^^^^^^^^^^^^^\n File \"c:\\Users\\Dan.QTIS\\.vscode\\extensions\\ms-python.python-2023.4.0\\pythonFiles\\lib\\python\\debugpy\\\\_vendored\\pydevd\\\\_pydevd\\_bundle\\pydevd\\_runpy.py\", line 294, in \\_get\\_code\\_from\\_file\n code = compile(f.read(), fname, 'exec')\n ^^^^^^^^^^^^^^^^^^^^^^^^^^^^^^^^\n File \"c:\\Users\\Dan.QTIS\\Desktop\\Dan\\All Projects Full\\Ai App\\main.py\", line 108\n def speak\\_button\\_clicked():\nIndentationError: expected an indented block after 'except' statement on line 105\nPS C:\\Users\\Dan.QTIS\\Desktop\\Dan\\All Projects Full\\Ai App> c:; cd 'c:\\Users\\Dan.QTIS\\Desktop\\Dan\\All Projects Full\\Ai App'; & 'C:\\Program Files\\Python311\\python.exe' 'c:\\Users\\Dan.QTIS\\.vscode\\extensions\\ms-python.python-2023.4.0\\pythonFiles\\lib\\python\\debugpy\\adapter/../..\\debugpy\\launcher' '50423' '--' 'c:\\Users\\Dan.QTIS\\Desktop\\Dan\\All Projects Full\\Ai App\\main.py' \nTraceback (most recent call last):\n File \"C:\\Program Files\\Python311\\Lib\\runpy.py\", line 198, in \\_run\\_module\\_as\\_main\n return \\_run\\_code(code, main\\_globals, None,\n ^^^^^^^^^^^^^^^^^^^^^^^^^^^^^^^^^^^\n File \"C:\\Program Files\\Python311\\Lib\\runpy.py\", line 88, in \\_run\\_code\n exec(code, run\\_globals)\n File \"c:\\Users\\Dan.QTIS\\.vscode\\extensions\\ms-python.python-2023.4.0\\pythonFiles\\lib\\python\\debugpy\\adapter/../..\\debugpy\\launcher/../..\\debugpy\\\\_\\_main\\_\\_.py\", line 39, in \n cli.main()\n File \"c:\\Users\\Dan.QTIS\\.vscode\\extensions\\ms-python.python-2023.4.0\\pythonFiles\\lib\\python\\debugpy\\adapter/../..\\debugpy\\launcher/../..\\debugpy/..\\debugpy\\server\\cli.py\", line 430, in main\n run()\n File \"c:\\Users\\Dan.QTIS\\.vscode\\extensions\\ms-python.python-2023.4.0\\pythonFiles\\lib\\python\\debugpy\\adapter/../..\\debugpy\\launcher/../..\\debugpy/..\\debugpy\\server\\cli.py\", line 284, in run\\_file\n runpy.run\\_path(target, run\\_name=\"\\_\\_main\\_\\_\")\n File \"c:\\Users\\Dan.QTIS\\.vscode\\extensions\\ms-python.python-2023.4.0\\pythonFiles\\lib\\python\\debugpy\\\\_vendored\\pydevd\\\\_pydevd\\_bundle\\pydevd\\_runpy.py\", line 320, in run\\_path\n code, fname = \\_get\\_code\\_from\\_file(run\\_name, path\\_name)\n ^^^^^^^^^^^^^^^^^^^^^^^^^^^^^^^^^^^^^^^^\n File \"c:\\Users\\Dan.QTIS\\.vscode\\extensions\\ms-python.python-2023.4.0\\pythonFiles\\lib\\python\\debugpy\\\\_vendored\\pydevd\\\\_pydevd\\_bundle\\pydevd\\_runpy.py\", line 294, in \\_get\\_code\\_from\\_file\n code = compile(f.read(), fname, 'exec')\n ^^^^^^^^^^^^^^^^^^^^^^^^^^^^^^^^\n File \"c:\\Users\\Dan.QTIS\\Desktop\\Dan\\All Projects Full\\Ai App\\main.py\", line 108\n def speak\\_button\\_clicked():\nIndentationError: expected an indented block after 'except' statement on line 105\nPS C:\\Users\\Dan.QTIS\\Desktop\\Dan\\All Projects Full\\Ai App> c:; cd 'c:\\Users\\Dan.QTIS\\Desktop\\Dan\\All Projects Full\\Ai App'; & 'C:\\Program Files\\Python311\\python.exe' 'c:\\Users\\Dan.QTIS\\.vscode\\extensions\\ms-python.python-2023.4.0\\pythonFiles\\lib\\python\\debugpy\\adapter/../..\\debugpy\\launcher' '50434' '--' 'c:\\Users\\Dan.QTIS\\Desktop\\Dan\\All Projects Full\\Ai App\\main.py' \nTraceback (most recent call last):\n File \"C:\\Program Files\\Python311\\Lib\\runpy.py\", line 198, in \\_run\\_module\\_as\\_main\n return \\_run\\_code(code, main\\_globals, None,\n ^^^^^^^^^^^^^^^^^^^^^^^^^^^^^^^^^^^\n File \"C:\\Program Files\\Python311\\Lib\\runpy.py\", line 88, in \\_run\\_code\n exec(code, run\\_globals)\n File \"c:\\Users\\Dan.QTIS\\.vscode\\extensions\\ms-python.python-2023.4.0\\pythonFiles\\lib\\python\\debugpy\\adapter/../..\\debugpy\\launcher/../..\\debugpy\\\\_\\_main\\_\\_.py\", line 39, in \n cli.main()\n File \"c:\\Users\\Dan.QTIS\\.vscode\\extensions\\ms-python.python-2023.4.0\\pythonFiles\\lib\\python\\debugpy\\adapter/../..\\debugpy\\launcher/../..\\debugpy/..\\debugpy\\server\\cli.py\", line 430, in main\n run()\n File \"c:\\Users\\Dan.QTIS\\.vscode\\extensions\\ms-python.python-2023.4.0\\pythonFiles\\lib\\python\\debugpy\\adapter/../..\\debugpy\\launcher/../..\\debugpy/..\\debugpy\\server\\cli.py\", line 284, in run\\_file\n runpy.run\\_path(target, run\\_name=\"\\_\\_main\\_\\_\")\n File \"c:\\Users\\Dan.QTIS\\.vscode\\extensions\\ms-python.python-2023.4.0\\pythonFiles\\lib\\python\\debugpy\\\\_vendored\\pydevd\\\\_pydevd\\_bundle\\pydevd\\_runpy.py\", line 320, in run\\_path\n code, fname = \\_get\\_code\\_from\\_file(run\\_name, path\\_name)\n ^^^^^^^^^^^^^^^^^^^^^^^^^^^^^^^^^^^^^^^^\n File \"c:\\Users\\Dan.QTIS\\.vscode\\extensions\\ms-python.python-2023.4.0\\pythonFiles\\lib\\python\\debugpy\\\\_vendored\\pydevd\\\\_pydevd\\_bundle\\pydevd\\_runpy.py\", line 294, in \\_get\\_code\\_from\\_file\n code = compile(f.read(), fname, 'exec')\n ^^^^^^^^^^^^^^^^^^^^^^^^^^^^^^^^\n File \"c:\\Users\\Dan.QTIS\\Desktop\\Dan\\All Projects Full\\Ai App\\main.py\", line 109\n def speak\\_button\\_clicked():\nIndentationError: expected an indented block after 'except' statement on line 105",
      "language": "en",
      "sentiment": {
        "neg": 0.031,
        "neu": 0.969,
        "pos": 0.0,
        "compound": -0.9231
      },
      "core_lexical": {
        "self_ref_freq": 0,
        "second_person_freq": 0,
        "token_count": 1031,
        "self_ref_ratio": 0.0,
        "second_person_ratio": 0.0
      },
      "lexical_features": {
        "adj_adv_freq": 89,
        "adj_adv_ratio": 0.0863239573229874,
        "self_ref_freq": 0,
        "self_ref_ratio": 0.0,
        "second_person_freq": 0,
        "second_person_ratio": 0.0,
        "token_count": 1031
      },
      "advanced_features": {
        "structural_features": {
          "avg_sentence_length": 1031.0,
          "clause_complexity": 4.0,
          "vocabulary_richness": 0.13286713286713286
        },
        "interaction_features": {
          "question_types": {
            "what": 0,
            "how": 0,
            "why": 0,
            "can_could": 0,
            "general": 0
          },
          "discourse_markers": {
            "elaboration": 0,
            "contrast": 0,
            "causality": 0,
            "hedging": 0
          }
        },
        "linguistic_features": {
          "verb_tense_dist": {
            "VB": 4,
            "VBP": 4,
            "VBN": 8
          },
          "named_entities": {
            "PERSON": 4,
            "GPE": 4
          }
        }
      },
      "expressive_label": 0,
      "anthropomorphic_label": 0
    },
    {
      "from": "gpt",
      "value": "It seems like you have a syntax error on line 105 of your code. The error message says \"IndentationError: expected an indented block after 'except' statement on line 105.\" This error usually occurs when you forget to indent the code inside a block, such as an `if` statement or a `try-except` block. Please check the indentation of the code after the `except` statement on line 105 and make sure it is properly indented.\n\nHere's an example of how to correctly indent a `try-except` block:\n```python\ntry:\n    # code to be executed that may raise an exception\nexcept SomeException:\n    # handle the exception\n```\nNotice how the code inside the `try` block is indented, and the code inside the `except` block is also indented. This is how you should indent your code as well.",
      "language": "en",
      "sentiment": {
        "neg": 0.178,
        "neu": 0.763,
        "pos": 0.059,
        "compound": -0.956
      },
      "core_lexical": {
        "self_ref_freq": 0,
        "second_person_freq": 5,
        "token_count": 164,
        "self_ref_ratio": 0.0,
        "second_person_ratio": 0.03048780487804878
      },
      "lexical_features": {
        "adj_adv_freq": 12,
        "adj_adv_ratio": 0.07317073170731707,
        "self_ref_freq": 0,
        "self_ref_ratio": 0.0,
        "second_person_freq": 5,
        "second_person_ratio": 0.03048780487804878,
        "token_count": 164
      },
      "advanced_features": {
        "structural_features": {
          "avg_sentence_length": 27.333333333333332,
          "clause_complexity": 0.6666666666666666,
          "vocabulary_richness": 0.5652173913043478
        },
        "interaction_features": {
          "question_types": {
            "what": 0,
            "how": 3,
            "why": 0,
            "can_could": 0,
            "general": 0
          },
          "discourse_markers": {
            "elaboration": 1,
            "contrast": 0,
            "causality": 0,
            "hedging": 0
          }
        },
        "linguistic_features": {
          "verb_tense_dist": {
            "VBZ": 8,
            "VBP": 2,
            "VBD": 1,
            "VB": 9,
            "VBN": 4
          },
          "named_entities": {}
        }
      }
    }
  ],
  "overall_sentiment": {
    "compound": -0.93955,
    "pos": 0.0295,
    "neu": 0.866,
    "neg": 0.1045
  },
  "overall_lexical": {
    "adj_adv_freq": 101,
    "adj_adv_ratio": 0.08451882845188284,
    "self_ref_freq": 0,
    "self_ref_ratio": 0.0,
    "second_person_freq": 5,
    "second_person_ratio": 0.0041841004184100415,
    "total_tokens": 1195
  },
  "overall_advanced": {
    "structural_features": {
      "avg_sentence_length": 529.1666666666666,
      "clause_complexity": 2.3333333333333335,
      "vocabulary_richness": 0.3490422620857403
    },
    "interaction_features": {
      "question_types": {
        "what": 0,
        "how": 3,
        "why": 0,
        "can_could": 0,
        "general": 0
      },
      "discourse_markers": {
        "elaboration": 1,
        "contrast": 0,
        "causality": 0,
        "hedging": 0
      }
    },
    "linguistic_features": {
      "verb_tense_dist": {
        "VB": 13,
        "VBP": 6,
        "VBN": 12,
        "VBZ": 8,
        "VBD": 1
      },
      "named_entities": {
        "PERSON": 4,
        "GPE": 4
      }
    }
  },
  "conversation_metadata": {
    "language_distribution": {
      "en": 2
    },
    "turn_count": 2,
    "total_tokens": 1195
  }
}